Workbook

Sheet 1. 기관 정보
A2: [작성시 참고사항] ㅇ 1번 시트(기관 정보), 2번 시트(신청 훈련과정 정보), 3번 시트(과정별 교과목 편성)을 모두 꼼꼼하게 작성 - 각 시트별 참고사항을 필독, 참고 요망(시트별 자동입력값이 있으므로 수식 삭제 X) ㅇ 신청서 내 작성정보가 누락되어 있거나 미기재되어 있을 경우 해당 과정은 심사대상에서 제외 ㅇ 시트별 참고사항은 필요한 자료 작성이 완료되었다면 삭제 후 제출 요망
A7: 기관명 | B7: 주소 (정확한 주소를 상세히 기재) | C7: 사업자등록번호 | D7: 훈련기관관리번호 (미발급 시 공란) | E7: 주요 훈련분야(NCS 대분류 기준) [드롭박스 선택] | F7: 주요 훈련방법 [드롭박스 선택] | G7: 훈련기관 인증 여부 (직업능력심사평가원)
A8: 모두의연구소 | B8: 서울특별시 강남구 강남대로 324 역삼디오슈페리움 2층 | C8: 517-88-00184 | D8: 202000579 | E8: 정보통신 | F8: 집체(대면) | G8: O
A10: 담당자 성명 및 직위 | B10: 담당자 연락처(☎) | C10: 담당자 연락처(H.P.) | D10: 담당자 연락처(E-mail) | E10: 담당자 외 사업 안내 메일링을 희망하는 기관 담당자 연락처(E-mail) | F10: 훈련 참여 문의처 ☎ (기업 등 고객 응대) | G10: 기관 로고(CI 등) 파일 별도 송부 요망
A11: 김영광 | B11: 010-9193-3163 | C11: 010-9193-3163 | D11: yk.kim@modulabs.co.kr | E11: modu.biz@modulabs.co.kr | F11: 010-7528-0184 | G11: O

Sheet 2. 신청 훈련과정 정보
A1: [작성방법(필독!)] 0. 모든 항목을 반드시 작성해야 하며, 미기재 항목이 있을 경우 심사대상에서 제외, 훈련기관명은 1번 시트 값이 자동입력되므로 직접입력 X 1. NCS 분류코드 : 해당 과정에 가장 주요하거나 많은 비중을 차지하는 내용을 토대로 각 분류상 가장 부합하는 코드를 작성(훈련기관 자체 판단) - NCS대분류명 기재 시 데이터박스 목록으로 설정, 대분류 숫자는 대분류명 선택시 자동입력되므로 직접입력 X 2. 비대면 실시간 운영 여부 : 집체형태 외 비대면 실시간 형태 운영 희망 시 'O' 체크(집체 형태는 기본적으로 모두 가능하며, 비대면 실시간 형태는 승인 과정에 한해 가능) 3. 훈련인원 : 기관에서 예상하는 해당 과정의 연간 훈련 실시인원 추정치 4. 훈련비 단가 : 1인, 1회 기준 훈련비용 5. 총 훈련비 : 총 훈련인원 X 훈련비 단가 6. 훈련일정 : 회차별 개설 예정 시기를 월 단위로 모두 기재('0월' 형태로 기재하거나 "연중 상시" 등 근로자 대상 충분히 안내 가능한 내용으로 작성) 7. 훈련실시장소 : 시/도 단위 및 정확한 주소를 각각 입력, 여러 장소에서 실시할 경우 셀 한개에 모두 입력(셀 구분 시 누락될 수 있음)
A6: 훈련기관명 | B6: 연번 | C6: NCS 대분류명 | D6: NCS 분류코드 | G6: 과정 유형 | H6: 훈련과정명 | I6: 비대면 실시간 운영 여부 | J6: 훈련시간 (H) | K6: 훈련기간 (일수) | L6: 훈련일정 | M6: 훈련인원(명) [예상 수요] | N6: 훈련비 단가(원) | O6: 총 훈련비(원) | P6: 최근 3년 이내('23~'25) 훈련과정 운영 이력 | Q6: 훈련 실시 장소
D7: 대 | E7: 중 | F7: 소 | Q7: 시/도 단위 | R7: 주소지 | S7: 문의처
A8: ='1. 기관 정보'!$A$8 -> 모두의연구소 | B8: 1 | C8: 정보통신 | D8: =_xlfn.IFS(C8="사업관리","01",C8="경영ㆍ회계ㆍ사무","02",C8="금융ㆍ보험","03",C8="교육ㆍ자연ㆍ사회과학","04",C8="법률ㆍ경찰ㆍ소방ㆍ교도ㆍ국방","05",C8="보건ㆍ의료","06",C8="사회복지ㆍ종교","07",C8="문화ㆍ예술ㆍ디자인ㆍ방송","08",C8="운전ㆍ운송","09",C8="영업판매","10",C8="경비ㆍ청소","11",C8="이용ㆍ숙박ㆍ여행ㆍ오락ㆍ스포츠","12", C8="음식서비스","13", C8="건설","14", C8="기계","15",C8="재료","16",C8="화학ㆍ바이오","17",C8="섬유ㆍ의복","18",C8="전기ㆍ전자","19",C8="정보통신","20",C8="식품가공","21",C8="인쇄ㆍ목재ㆍ가구ㆍ공예","22",C8="환경ㆍ에너지ㆍ안전","23",C8="농림어업","24") -> 20 | E8: 01 | F8: 07 | G8: AI융합형 | H8: 클로드로 업무자동화 시작하기 | I8: X | J8: 8 | K8: 1 | L8: 연중 상시 | M8: 80 | N8: 200000 | O8: =M8*N8 -> 16000000 | P8: O | Q8: 서울 경기 지역 | R8: 신청 기업 사업장에 찾아가는 훈련 | S8: 010-7528-0184
A9: ='1. 기관 정보'!$A$8 -> 모두의연구소 | B9: 2 | C9: 정보통신 | D9: =_xlfn.IFS(C9="사업관리","01",C9="경영ㆍ회계ㆍ사무","02",C9="금융ㆍ보험","03",C9="교육ㆍ자연ㆍ사회과학","04",C9="법률ㆍ경찰ㆍ소방ㆍ교도ㆍ국방","05",C9="보건ㆍ의료","06",C9="사회복지ㆍ종교","07",C9="문화ㆍ예술ㆍ디자인ㆍ방송","08",C9="운전ㆍ운송","09",C9="영업판매","10",C9="경비ㆍ청소","11",C9="이용ㆍ숙박ㆍ여행ㆍ오락ㆍ스포츠","12", C9="음식서비스","13", C9="건설","14", C9="기계","15",C9="재료","16",C9="화학ㆍ바이오","17",C9="섬유ㆍ의복","18",C9="전기ㆍ전자","19",C9="정보통신","20",C9="식품가공","21",C9="인쇄ㆍ목재ㆍ가구ㆍ공예","22",C9="환경ㆍ에너지ㆍ안전","23",C9="농림어업","24") -> 20 | E9: 01 | F9: 07 | G9: AI융합형 | H9: 비개발자를 위한 에이전틱 코딩 | I9: X | J9: 8 | K9: 1 | L9: 연중 상시 | M9: 60 | N9: 250000 | O9: =M9*N9 -> 15000000 | P9: O | Q9: 서울 경기 지역 | R9: 신청 기업 사업장에 찾아가는 훈련 | S9: 010-7528-0184
A10: ='1. 기관 정보'!$A$8 -> 모두의연구소 | B10: 3 | C10: 정보통신 | D10: =_xlfn.IFS(C10="사업관리","01",C10="경영ㆍ회계ㆍ사무","02",C10="금융ㆍ보험","03",C10="교육ㆍ자연ㆍ사회과학","04",C10="법률ㆍ경찰ㆍ소방ㆍ교도ㆍ국방","05",C10="보건ㆍ의료","06",C10="사회복지ㆍ종교","07",C10="문화ㆍ예술ㆍ디자인ㆍ방송","08",C10="운전ㆍ운송","09",C10="영업판매","10",C10="경비ㆍ청소","11",C10="이용ㆍ숙박ㆍ여행ㆍ오락ㆍ스포츠","12", C10="음식서비스","13", C10="건설","14", C10="기계","15",C10="재료","16",C10="화학ㆍ바이오","17",C10="섬유ㆍ의복","18",C10="전기ㆍ전자","19",C10="정보통신","20",C10="식품가공","21",C10="인쇄ㆍ목재ㆍ가구ㆍ공예","22",C10="환경ㆍ에너지ㆍ안전","23",C10="농림어업","24") -> 20 | E10: 01 | F10: 07 | G10: AI융합형 | H10: 실무형 노코드 멀티 에이전트 과정 | I10: X | J10: 8 | K10: 1 | L10: 연중 상시 | M10: 60 | N10: 250000 | O10: =M10*N10 -> 15000000 | P10: O | Q10: 서울 경기 지역 | R10: 신청 기업 사업장에 찾아가는 훈련 | S10: 010-7528-0184
A11: ='1. 기관 정보'!$A$8 -> 모두의연구소 | B11: 4 | C11: 정보통신 | D11: =_xlfn.IFS(C11="사업관리","01",C11="경영ㆍ회계ㆍ사무","02",C11="금융ㆍ보험","03",C11="교육ㆍ자연ㆍ사회과학","04",C11="법률ㆍ경찰ㆍ소방ㆍ교도ㆍ국방","05",C11="보건ㆍ의료","06",C11="사회복지ㆍ종교","07",C11="문화ㆍ예술ㆍ디자인ㆍ방송","08",C11="운전ㆍ운송","09",C11="영업판매","10",C11="경비ㆍ청소","11",C11="이용ㆍ숙박ㆍ여행ㆍ오락ㆍ스포츠","12", C11="음식서비스","13", C11="건설","14", C11="기계","15",C11="재료","16",C11="화학ㆍ바이오","17",C11="섬유ㆍ의복","18",C11="전기ㆍ전자","19",C11="정보통신","20",C11="식품가공","21",C11="인쇄ㆍ목재ㆍ가구ㆍ공예","22",C11="환경ㆍ에너지ㆍ안전","23",C11="농림어업","24") -> 20 | E11: 01 | F11: 07 | G11: AI융합형 | H11: 멀티 에이전트 개발을 위한 하네스 엔지니어링 | I11: X | J11: 8 | K11: 1 | L11: 연중 상시 | M11: 50 | N11: 300000 | O11: =M11*N11 -> 15000000 | P11: O | Q11: 서울 경기 지역 | R11: 신청 기업 사업장에 찾아가는 훈련 | S11: 010-7528-0184
A12: ='1. 기관 정보'!$A$8 -> 모두의연구소 | B12: 5 | C12: 정보통신 | D12: =_xlfn.IFS(C12="사업관리","01",C12="경영ㆍ회계ㆍ사무","02",C12="금융ㆍ보험","03",C12="교육ㆍ자연ㆍ사회과학","04",C12="법률ㆍ경찰ㆍ소방ㆍ교도ㆍ국방","05",C12="보건ㆍ의료","06",C12="사회복지ㆍ종교","07",C12="문화ㆍ예술ㆍ디자인ㆍ방송","08",C12="운전ㆍ운송","09",C12="영업판매","10",C12="경비ㆍ청소","11",C12="이용ㆍ숙박ㆍ여행ㆍ오락ㆍ스포츠","12", C12="음식서비스","13", C12="건설","14", C12="기계","15",C12="재료","16",C12="화학ㆍ바이오","17",C12="섬유ㆍ의복","18",C12="전기ㆍ전자","19",C12="정보통신","20",C12="식품가공","21",C12="인쇄ㆍ목재ㆍ가구ㆍ공예","22",C12="환경ㆍ에너지ㆍ안전","23",C12="농림어업","24") -> 20 | E12: 01 | F12: 07 | G12: AI융합형 | H12: 상업용 AI콘텐츠 제작 실전 | I12: X | J12: 8 | K12: 1 | L12: 연중 상시 | M12: 80 | N12: 200000 | O12: =M12*N12 -> 16000000 | P12: O | Q12: 서울 경기 지역 | R12: 신청 기업 사업장에 찾아가는 훈련 | S12: 010-7528-0184
A13: ='1. 기관 정보'!$A$8 -> 모두의연구소 | B13: 10 | D13: =_xlfn.IFS(C13="사업관리","01",C13="경영ㆍ회계ㆍ사무","02",C13="금융ㆍ보험","03",C13="교육ㆍ자연ㆍ사회과학","04",C13="법률ㆍ경찰ㆍ소방ㆍ교도ㆍ국방","05",C13="보건ㆍ의료","06",C13="사회복지ㆍ종교","07",C13="문화ㆍ예술ㆍ디자인ㆍ방송","08",C13="운전ㆍ운송","09",C13="영업판매","10",C13="경비ㆍ청소","11",C13="이용ㆍ숙박ㆍ여행ㆍ오락ㆍ스포츠","12", C13="음식서비스","13", C13="건설","14", C13="기계","15",C13="재료","16",C13="화학ㆍ바이오","17",C13="섬유ㆍ의복","18",C13="전기ㆍ전자","19",C13="정보통신","20",C13="식품가공","21",C13="인쇄ㆍ목재ㆍ가구ㆍ공예","22",C13="환경ㆍ에너지ㆍ안전","23",C13="농림어업","24") -> #N/A
A14: ='1. 기관 정보'!$A$8 -> 모두의연구소 | B14: 11 | D14: =_xlfn.IFS(C14="사업관리","01",C14="경영ㆍ회계ㆍ사무","02",C14="금융ㆍ보험","03",C14="교육ㆍ자연ㆍ사회과학","04",C14="법률ㆍ경찰ㆍ소방ㆍ교도ㆍ국방","05",C14="보건ㆍ의료","06",C14="사회복지ㆍ종교","07",C14="문화ㆍ예술ㆍ디자인ㆍ방송","08",C14="운전ㆍ운송","09",C14="영업판매","10",C14="경비ㆍ청소","11",C14="이용ㆍ숙박ㆍ여행ㆍ오락ㆍ스포츠","12", C14="음식서비스","13", C14="건설","14", C14="기계","15",C14="재료","16",C14="화학ㆍ바이오","17",C14="섬유ㆍ의복","18",C14="전기ㆍ전자","19",C14="정보통신","20",C14="식품가공","21",C14="인쇄ㆍ목재ㆍ가구ㆍ공예","22",C14="환경ㆍ에너지ㆍ안전","23",C14="농림어업","24") -> #N/A
A15: ='1. 기관 정보'!$A$8 -> 모두의연구소 | B15: 12 | D15: =_xlfn.IFS(C15="사업관리","01",C15="경영ㆍ회계ㆍ사무","02",C15="금융ㆍ보험","03",C15="교육ㆍ자연ㆍ사회과학","04",C15="법률ㆍ경찰ㆍ소방ㆍ교도ㆍ국방","05",C15="보건ㆍ의료","06",C15="사회복지ㆍ종교","07",C15="문화ㆍ예술ㆍ디자인ㆍ방송","08",C15="운전ㆍ운송","09",C15="영업판매","10",C15="경비ㆍ청소","11",C15="이용ㆍ숙박ㆍ여행ㆍ오락ㆍ스포츠","12", C15="음식서비스","13", C15="건설","14", C15="기계","15",C15="재료","16",C15="화학ㆍ바이오","17",C15="섬유ㆍ의복","18",C15="전기ㆍ전자","19",C15="정보통신","20",C15="식품가공","21",C15="인쇄ㆍ목재ㆍ가구ㆍ공예","22",C15="환경ㆍ에너지ㆍ안전","23",C15="농림어업","24") -> #N/A
A16: ='1. 기관 정보'!$A$8 -> 모두의연구소 | B16: 13 | D16: =_xlfn.IFS(C16="사업관리","01",C16="경영ㆍ회계ㆍ사무","02",C16="금융ㆍ보험","03",C16="교육ㆍ자연ㆍ사회과학","04",C16="법률ㆍ경찰ㆍ소방ㆍ교도ㆍ국방","05",C16="보건ㆍ의료","06",C16="사회복지ㆍ종교","07",C16="문화ㆍ예술ㆍ디자인ㆍ방송","08",C16="운전ㆍ운송","09",C16="영업판매","10",C16="경비ㆍ청소","11",C16="이용ㆍ숙박ㆍ여행ㆍ오락ㆍ스포츠","12", C16="음식서비스","13", C16="건설","14", C16="기계","15",C16="재료","16",C16="화학ㆍ바이오","17",C16="섬유ㆍ의복","18",C16="전기ㆍ전자","19",C16="정보통신","20",C16="식품가공","21",C16="인쇄ㆍ목재ㆍ가구ㆍ공예","22",C16="환경ㆍ에너지ㆍ안전","23",C16="농림어업","24") -> #N/A
A17: ='1. 기관 정보'!$A$8 -> 모두의연구소 | B17: 14 | D17: =_xlfn.IFS(C17="사업관리","01",C17="경영ㆍ회계ㆍ사무","02",C17="금융ㆍ보험","03",C17="교육ㆍ자연ㆍ사회과학","04",C17="법률ㆍ경찰ㆍ소방ㆍ교도ㆍ국방","05",C17="보건ㆍ의료","06",C17="사회복지ㆍ종교","07",C17="문화ㆍ예술ㆍ디자인ㆍ방송","08",C17="운전ㆍ운송","09",C17="영업판매","10",C17="경비ㆍ청소","11",C17="이용ㆍ숙박ㆍ여행ㆍ오락ㆍ스포츠","12", C17="음식서비스","13", C17="건설","14", C17="기계","15",C17="재료","16",C17="화학ㆍ바이오","17",C17="섬유ㆍ의복","18",C17="전기ㆍ전자","19",C17="정보통신","20",C17="식품가공","21",C17="인쇄ㆍ목재ㆍ가구ㆍ공예","22",C17="환경ㆍ에너지ㆍ안전","23",C17="농림어업","24") -> #N/A
A18: ='1. 기관 정보'!$A$8 -> 모두의연구소 | B18: 15 | D18: =_xlfn.IFS(C18="사업관리","01",C18="경영ㆍ회계ㆍ사무","02",C18="금융ㆍ보험","03",C18="교육ㆍ자연ㆍ사회과학","04",C18="법률ㆍ경찰ㆍ소방ㆍ교도ㆍ국방","05",C18="보건ㆍ의료","06",C18="사회복지ㆍ종교","07",C18="문화ㆍ예술ㆍ디자인ㆍ방송","08",C18="운전ㆍ운송","09",C18="영업판매","10",C18="경비ㆍ청소","11",C18="이용ㆍ숙박ㆍ여행ㆍ오락ㆍ스포츠","12", C18="음식서비스","13", C18="건설","14", C18="기계","15",C18="재료","16",C18="화학ㆍ바이오","17",C18="섬유ㆍ의복","18",C18="전기ㆍ전자","19",C18="정보통신","20",C18="식품가공","21",C18="인쇄ㆍ목재ㆍ가구ㆍ공예","22",C18="환경ㆍ에너지ㆍ안전","23",C18="농림어업","24") -> #N/A
A19: ='1. 기관 정보'!$A$8 -> 모두의연구소 | B19: 16 | D19: =_xlfn.IFS(C19="사업관리","01",C19="경영ㆍ회계ㆍ사무","02",C19="금융ㆍ보험","03",C19="교육ㆍ자연ㆍ사회과학","04",C19="법률ㆍ경찰ㆍ소방ㆍ교도ㆍ국방","05",C19="보건ㆍ의료","06",C19="사회복지ㆍ종교","07",C19="문화ㆍ예술ㆍ디자인ㆍ방송","08",C19="운전ㆍ운송","09",C19="영업판매","10",C19="경비ㆍ청소","11",C19="이용ㆍ숙박ㆍ여행ㆍ오락ㆍ스포츠","12", C19="음식서비스","13", C19="건설","14", C19="기계","15",C19="재료","16",C19="화학ㆍ바이오","17",C19="섬유ㆍ의복","18",C19="전기ㆍ전자","19",C19="정보통신","20",C19="식품가공","21",C19="인쇄ㆍ목재ㆍ가구ㆍ공예","22",C19="환경ㆍ에너지ㆍ안전","23",C19="농림어업","24") -> #N/A
A20: ='1. 기관 정보'!$A$8 -> 모두의연구소 | B20: 17 | D20: =_xlfn.IFS(C20="사업관리","01",C20="경영ㆍ회계ㆍ사무","02",C20="금융ㆍ보험","03",C20="교육ㆍ자연ㆍ사회과학","04",C20="법률ㆍ경찰ㆍ소방ㆍ교도ㆍ국방","05",C20="보건ㆍ의료","06",C20="사회복지ㆍ종교","07",C20="문화ㆍ예술ㆍ디자인ㆍ방송","08",C20="운전ㆍ운송","09",C20="영업판매","10",C20="경비ㆍ청소","11",C20="이용ㆍ숙박ㆍ여행ㆍ오락ㆍ스포츠","12", C20="음식서비스","13", C20="건설","14", C20="기계","15",C20="재료","16",C20="화학ㆍ바이오","17",C20="섬유ㆍ의복","18",C20="전기ㆍ전자","19",C20="정보통신","20",C20="식품가공","21",C20="인쇄ㆍ목재ㆍ가구ㆍ공예","22",C20="환경ㆍ에너지ㆍ안전","23",C20="농림어업","24") -> #N/A
A21: ='1. 기관 정보'!$A$8 -> 모두의연구소 | B21: 18 | D21: =_xlfn.IFS(C21="사업관리","01",C21="경영ㆍ회계ㆍ사무","02",C21="금융ㆍ보험","03",C21="교육ㆍ자연ㆍ사회과학","04",C21="법률ㆍ경찰ㆍ소방ㆍ교도ㆍ국방","05",C21="보건ㆍ의료","06",C21="사회복지ㆍ종교","07",C21="문화ㆍ예술ㆍ디자인ㆍ방송","08",C21="운전ㆍ운송","09",C21="영업판매","10",C21="경비ㆍ청소","11",C21="이용ㆍ숙박ㆍ여행ㆍ오락ㆍ스포츠","12", C21="음식서비스","13", C21="건설","14", C21="기계","15",C21="재료","16",C21="화학ㆍ바이오","17",C21="섬유ㆍ의복","18",C21="전기ㆍ전자","19",C21="정보통신","20",C21="식품가공","21",C21="인쇄ㆍ목재ㆍ가구ㆍ공예","22",C21="환경ㆍ에너지ㆍ안전","23",C21="농림어업","24") -> #N/A
A22: ='1. 기관 정보'!$A$8 -> 모두의연구소 | B22: 19 | D22: =_xlfn.IFS(C22="사업관리","01",C22="경영ㆍ회계ㆍ사무","02",C22="금융ㆍ보험","03",C22="교육ㆍ자연ㆍ사회과학","04",C22="법률ㆍ경찰ㆍ소방ㆍ교도ㆍ국방","05",C22="보건ㆍ의료","06",C22="사회복지ㆍ종교","07",C22="문화ㆍ예술ㆍ디자인ㆍ방송","08",C22="운전ㆍ운송","09",C22="영업판매","10",C22="경비ㆍ청소","11",C22="이용ㆍ숙박ㆍ여행ㆍ오락ㆍ스포츠","12", C22="음식서비스","13", C22="건설","14", C22="기계","15",C22="재료","16",C22="화학ㆍ바이오","17",C22="섬유ㆍ의복","18",C22="전기ㆍ전자","19",C22="정보통신","20",C22="식품가공","21",C22="인쇄ㆍ목재ㆍ가구ㆍ공예","22",C22="환경ㆍ에너지ㆍ안전","23",C22="농림어업","24") -> #N/A
A23: ='1. 기관 정보'!$A$8 -> 모두의연구소 | B23: 20 | D23: =_xlfn.IFS(C23="사업관리","01",C23="경영ㆍ회계ㆍ사무","02",C23="금융ㆍ보험","03",C23="교육ㆍ자연ㆍ사회과학","04",C23="법률ㆍ경찰ㆍ소방ㆍ교도ㆍ국방","05",C23="보건ㆍ의료","06",C23="사회복지ㆍ종교","07",C23="문화ㆍ예술ㆍ디자인ㆍ방송","08",C23="운전ㆍ운송","09",C23="영업판매","10",C23="경비ㆍ청소","11",C23="이용ㆍ숙박ㆍ여행ㆍ오락ㆍ스포츠","12", C23="음식서비스","13", C23="건설","14", C23="기계","15",C23="재료","16",C23="화학ㆍ바이오","17",C23="섬유ㆍ의복","18",C23="전기ㆍ전자","19",C23="정보통신","20",C23="식품가공","21",C23="인쇄ㆍ목재ㆍ가구ㆍ공예","22",C23="환경ㆍ에너지ㆍ안전","23",C23="농림어업","24") -> #N/A
A24: ='1. 기관 정보'!$A$8 -> 모두의연구소 | B24: 21 | D24: =_xlfn.IFS(C24="사업관리","01",C24="경영ㆍ회계ㆍ사무","02",C24="금융ㆍ보험","03",C24="교육ㆍ자연ㆍ사회과학","04",C24="법률ㆍ경찰ㆍ소방ㆍ교도ㆍ국방","05",C24="보건ㆍ의료","06",C24="사회복지ㆍ종교","07",C24="문화ㆍ예술ㆍ디자인ㆍ방송","08",C24="운전ㆍ운송","09",C24="영업판매","10",C24="경비ㆍ청소","11",C24="이용ㆍ숙박ㆍ여행ㆍ오락ㆍ스포츠","12", C24="음식서비스","13", C24="건설","14", C24="기계","15",C24="재료","16",C24="화학ㆍ바이오","17",C24="섬유ㆍ의복","18",C24="전기ㆍ전자","19",C24="정보통신","20",C24="식품가공","21",C24="인쇄ㆍ목재ㆍ가구ㆍ공예","22",C24="환경ㆍ에너지ㆍ안전","23",C24="농림어업","24") -> #N/A
... A28: ='1. 기관 정보'!$A$8 -> 모두의연구소 | B28: 25 | D28: =_xlfn.IFS(C28="사업관리","01",C28="경영ㆍ회계ㆍ사무","02",C28="금융ㆍ보험","03",C28="교육ㆍ자연ㆍ사회과학","04",C28="법률ㆍ경찰ㆍ소방ㆍ교도ㆍ국방","05",C28="보건ㆍ의료","06",C28="사회복지ㆍ종교","07",C28="문화ㆍ예술ㆍ디자인ㆍ방송","08",C28="운전ㆍ운송","09",C28="영업판매","10",C28="경비ㆍ청소","11",C28="이용ㆍ숙박ㆍ여행ㆍ오락ㆍ스포츠","12", C28="음식서비스","13", C28="건설","14", C28="기계","15",C28="재료","16",C28="화학ㆍ바이오","17",C28="섬유ㆍ의복","18",C28="전기ㆍ전자","19",C28="정보통신","20",C28="식품가공","21",C28="인쇄ㆍ목재ㆍ가구ㆍ공예","22",C28="환경ㆍ에너지ㆍ안전","23",C28="농림어업","24") -> #N/A

Sheet 3. 과정별 교과목 편성
A2: [작성방법(필독!)] 0. 신청한 과정 수만큼 아래 표 양식을 복사하여 추가 입력, 과정 교과목이 8개를 초과할 경우 자체 추가하여 입력 1. 연번 : 추가된 표 양식만큼 자동으로 입력되므로, 직접 인력 X 2. 훈련과정명 : 연번에 따라 2번 시트값이 자동으로 입력되므로, 직접 입력 X 3. 훈련목표 : 본 과정을 통한 목표, 목적에 대해 간략히 기재(HRD-Net 과정 신청 시 입력사항과 동일) 4. 훈련대상 : 특정 직군, 직급, 경력(연차) 등 기업/근로자가 과정 선택 시 참고할 수 있는 수준으로 기재 5. 훈련시간 : 연번에 따라 2번 시트값이 자동으로 입력되므로, 직접 입력 X 6. 비대면 실시간 가능 여부 : 연번에 따라 2번 시트값이 자동으로 입력되므로, 직접 입력 X 7. 훈련일정 : 연번에 따라 2번 시트값이 자동으로 입력되므로, 직접 입력 X 8. 과정 소개 또는 부가 안내 : 기업/근로자를 대상으로 한, 과정에 대한 간략한 소개 혹은 해당 시트 내 정보 외 추가 안내가 필요한 사항에 대해 기재 9. 교과목, 단원, 세부내용 : 과정 커리큘럼 등에 대해 기재(HRD-Net 과정 신청 시 입력사항과 동일) 10. 편성시간 : 교과목별 편성시간(시간단위 숫자만 입력) 11. 교강사 프로필 : 과정 심사 / 훈련생 안내 시 필요하다고 판단되는 프로필 기재(기재된 사항은 훈련기관에서 개인정보 동의를 득한 내용으로 간주, 확인 必), 셀 간 병합 가능 12. 시설장비교재 : 훈련에 소요되는 장비, 시설, 교재 등을 상세하게 기재(셀 간 병합 가능)
A4: 연번 | B4: 훈련과정명 | D4: 교과목 | E4: 단원(모듈) | F4: 세부내용 | G4: 편성시간 | H4: 교강사 프로필(요약) | I4: 시설, 장비, 교재
A5: =COUNTIF(INDIRECT("$A$3:A" & ROW()-1), "연번") -> 1 | B5: =VLOOKUP(A5,'2. 신청 훈련과정 정보'!$B$8:$H$1048576,7,0) -> 클로드로 업무자동화 시작하기 | D5: Cowork & Skill 활용 업무 자동화 | E5: Module 1. AI 데스크톱 비서와 첫 만남 — Cowork 입문 | F5: ① Cowork란 무엇인가: 채팅 vs Cowork의 결정적 차이 - 질문에 답하는 AI → 직접 일하는 AI: 에이전트형 작업 모드 이해 - 데스크톱 파일/폴더에 직접 접근해서 읽고, 정리하고, 만들어주는 구조 ② 설치와 첫 실행 - Claude Desktop 설치 → Cowork 탭 진입 → 작업 폴더 지정 - 권한 설계의 중요성: 접근 폴더 범위, 승인 체크포인트, 삭제 전 확인 - 커넥터 vs 브라우저 vs 화면 제어: Cowork의 3가지 실행 방식 이해 ③ [실습] Cowork 설치 + Downloads 폴더 파일 유형별 자동 분류 체험 | G5: 2H | H5: • AI 업무 자동화 교육 경력 3년 이상 • 비개발자 대상 노코드 자동화 교육 경험 • Claude Cowork / Skill 실무 활용 경험 • 관련 분야: AI 리터러시, 업무 프로세스 혁신, DX 컨설팅 등 | I5: [교재] 자체 제작 교재 · 강의별 트렌드 반영 · 자체 제작 및 고도화 [도구] 클로드 Pro 이상, (Cowork,Skill)
A6: 훈련목표(목적 등) | B6: Claude Cowork과 Skill을 활용하여 반복 업무를 자연어 명령만으로 자동화하고, 스케줄 기반 완전 자동화 루틴을 독립적으로 구축할 수 있다. | E6: Module 2. 말로 시키는 업무 처리 — 실무 자동화 실전 | F6: ① 문서·데이터 자동화 - PDF 데이터 추출 → 엑셀 정리, 영수증 → 경비 보고서 자동 생성 - 회의록 종합 → 월간 리포트 작성, 다국어 번역·포맷 변환 ② 브라우저 연동과 커넥터 활용 - Claude in Chrome 연결: 웹 리서치 → 스프레드시트 정리 자동화 - 플러그인 마켓: 업무 분야별 플러그인 탐색과 설치 - AI가 실수했을 때: 결과 검토, 되돌리기, 재지시 패턴 ③ [실습] 실무 업무 1건 Cowork으로 자동화 (데이터 정리 or 리포트 생성) | G6: 3H
A7: 훈련대상 | B7: 권장 대상: · 엑셀 정리, 보고서 작성, 데이터 취합 등 반복 업무에 시간을 많이 쓰는 실무자 · AI 도구를 처음 접하지만 업무 효율화에 관심이 높은 중소기업 임직원 · ChatGPT 등 채팅형 AI는 써봤지만, 파일을 직접 다루는 에이전트형 AI는 처음인 분 | E7: Module 3. 한 번 만들고 계속 쓴다 — Skill 설계와 스케줄 자동화 | F7: ① Skill이란: 반복 작업을 재사용 가능한 모듈로 저장하기 - '수동 실행 → Skill 저장 → 스케줄 자동화' 3단계 핵심 흐름 - 나만의 커스텀 Skill 설계: 작업 절차 문서화와 조건 분기 설정 ② 예약 작업(Scheduled Tasks)으로 완전 자동화 - 매일/매주 반복 실행 설정: 아침 업무 루틴 자동화 시나리오 - Plugin Create: 우리 팀만의 커스텀 플러그인 제작 입문 - 조직 내 확산 전략: 팀원과 Skill 공유, 업무 표준화 ③ [실습] Skill 저장 → 스케줄 등록 → 나만의 자동화 루틴 완성 및 시연 | G7: 3H
A8: 훈련시간(H) | B8: =VLOOKUP(B5,'2. 신청 훈련과정 정보'!$H$8:$J$1048576,3,0) -> 8
A9: 비대면 실시간 가능 여부 | B9: =VLOOKUP(B5,'2. 신청 훈련과정 정보'!$H$8:$J$1048576,2,0) -> X
A10: 훈련일정 | B10: =VLOOKUP(B5,'2. 신청 훈련과정 정보'!$H$8:$L$1048576,5,0) -> 연중 상시
A11: 과정 소개(요약) 또는 부가 안내 | B11: "코딩 한 줄 없이, 말 한마디로 AI 비서를 만들어 보세요." 본 과정은 프로그래밍 경험이 전혀 없는 비개발자를 위해 설계된 AI 업무 자동화 입문 과정입니다. 이 과정을 마치면, 채팅에 답만 하던 AI를 넘어 데스크톱 파일을 직접 읽고, 정리하고, 만들어주는 '일하는 AI'를 다룰 수 있게 됩니다.
A15: 연번 | B15: 훈련과정명 | D15: 교과목 | E15: 단원(모듈) | F15: 세부내용 | G15: 편성시간 | H15: 교강사 프로필(요약) | I15: 시설, 장비, 교재
A16: =COUNTIF(INDIRECT("$A$3:A" & ROW()-1), "연번") -> 2 | B16: =VLOOKUP(A16,'2. 신청 훈련과정 정보'!$B$8:$H$1048576,7,0) -> 비개발자를 위한 에이전틱 코딩 | D16: 클로드 코드 제로베이스 실전 | E16: Module 1. 두려움 없이 시작하기 — 설치부터 첫 결과물까지 | F16: ① 개발 환경 이해: 비개발자 눈높이로 보는 터미널·코드·파일 구조 - '코딩'이 아니라 'AI에게 말로 시키는 것': 마인드셋 전환 - 터미널 공포증 극복: 꼭 필요한 명령어 5개만 익히기 ② 클로드 코드 설치와 첫 실행 - Node.js 설치 → 클로드 코드 설치 → 인증까지 단계별 따라하기 - 첫 대화: '안녕' 대신 '이 폴더에 있는 파일 목록 보여줘'로 시작하기 - 권한 시스템 이해: 허용/거절 판단 기준 세우기 ③ [실습] 클로드 코드 설치 완료 + 자연어로 간단한 웹페이지 1개 만들기 | G16: 2H | H16: • AI 도구 활용 교육 경력 3년 이상 • 비개발자 대상 코딩/자동화 교육 경험 • 클로드 코드 실무 활용 및 프로젝트 수행 경험 • 관련 분야: AI 리터러시, 업무 자동화, 테크 교육 등 | I16: [교재] 자체 제작 교재 · 강의별 트렌드 반영 · 자체 제작 및 고도화 [도구] 클로드 Pro 이상, claude code, Node.js, 엑셀, MCP
A17: 훈련목표(목적 등) | B17: 터미널과 클로드 코드를 활용하여 자연어 명령으로 업무 도구를 직접 만들고, CLAUDE.md와 MCP 서버를 설정하여 나만의 자동화 작업 환경을 구축할 수 있다. | E17: Module 2. 자연어로 업무 도구 만들기 — 내 일을 코드로 바꾸다 | F17: ① 업무 자동화 설계: 반복 업무를 자연어 명령으로 분해하기 - 엑셀/CSV 데이터 정리·분석 자동화 - 보고서 자동 생성, 파일 일괄 처리, 이메일 템플릿 등 실무 시나리오 ② 에러와 친해지기: AI와 함께하는 문제 해결 - 에러 메시지 읽는 법: 빨간 글씨가 나와도 당황하지 않기 - '이거 왜 안 돼?'라고 물으면 클로드가 고쳐주는 디버깅 패턴 - 되돌리기와 버전 관리: 실수해도 복구하는 안전장치 ③ [실습] 내 실무 데이터로 자동화 스크립트 1개 완성 | G17: 3H
A18: 훈련대상 | B18: 권장 대상: · Cowork(GUI 자동화)을 넘어 터미널 기반 자동화에 도전해 보고 싶은 분 · '코딩을 배우고 싶지만 시작이 두려운' 비개발자 · 엑셀 매크로 수준을 넘어, AI가 코드를 대신 짜주는 경험을 해보고 싶은 분 · 팀에 개발자가 없어 간단한 도구를 직접 만들어야 하는 중소기업 실무자 | E18: Module 3. 나만의 AI 작업 환경 구축하기 — 한 번 만들고 계속 쓰다 | F18: ① CLAUDE.md 작성: 나만의 작업 규칙을 AI에게 기억시키기 - '항상 한국어로 답해줘', '이 폴더 구조를 따라줘' 등 규칙 설계 - 반복 지시 없이 일관된 결과물을 얻는 하네스 입문 ② MCP 서버 연결: 외부 서비스와 AI 연동 맛보기 - 파일시스템, 웹 검색 등 기본 MCP 도구 연결 실습 - 비개발자도 가능한 플러그인 방식의 확장 전략 ③ [실습] CLAUDE.md + MCP 설정 완료, 나만의 자동화 워크플로우 시연 | G18: 3H
A19: 훈련시간(H) | B19: =VLOOKUP(B16,'2. 신청 훈련과정 정보'!$H$8:$J$1048576,3,0) -> 8
A20: 비대면 실시간 가능 여부 | B20: =VLOOKUP(B16,'2. 신청 훈련과정 정보'!$H$8:$J$1048576,2,0) -> X
A21: 훈련일정 | B21: =VLOOKUP(B16,'2. 신청 훈련과정 정보'!$H$8:$L$1048576,5,0) -> 연중 상시
A22: 과정 소개(요약) 또는 부가 안내 | B22: "터미널 공포증 안녕" 본 과정은 코딩 경험이 전혀 없는 비개발자가 클로드 코드(Claude Code)를 활용해 자연어만으로 업무 도구를 직접 만들어보는 에이전틱 코딩 입문 과정입니다. 이 과정을 마치면, '개발자 없이는 불가능했던 일'을 혼자서 해내는 자신감과 실무 역량을 갖추게 됩니다.
A25: 연번 | B25: 훈련과정명 | D25: 교과목 | E25: 단원(모듈) | F25: 세부내용 | G25: 편성시간 | H25: 교강사 프로필(요약) | I25: 시설, 장비, 교재
A26: =COUNTIF(INDIRECT("$A$3:A" & ROW()-1), "연번") -> 3 | B26: =VLOOKUP(A26,'2. 신청 훈련과정 정보'!$B$8:$H$1048576,7,0) -> 실무형 노코드 멀티 에이전트 과정 | D26: Cowork 하네스 엔지니어링 실전 | E26: Module 1. 말을 알아야 다룬다 — Cowork와 하네스의 이해 | F26: ① 채팅 AI vs 에이전트 AI: 왜 Cowork에는 '하네스'가 필요한가 - 질문에 답하는 AI → 직접 파일을 만지고 실행하는 AI의 본질적 차이 - 하네스 엔지니어링 비유: 말(Cowork AI) / 하네스(규칙·권한·Skill) / 기수(나) - 하네스 없는 AI의 위험: 엉뚱한 파일 삭제, 작업 폭주, 결과물 불일치 사례 ② Cowork 첫 실행과 '나의 첫 하네스' 설계 - Claude Desktop 설치 → Cowork 탭 진입 → 작업 폴더 지정 - 비개발자의 가드레일: 접근 폴더 범위, 승인 체크포인트, 삭제 전 확인 규칙 - 커넥터 → 브라우저 → 화면 제어: 안전한 실행 방식 우선순위 이해 ③ [실습] Cowork 설치 + 나의 첫 하네스(권한 경계·작업 규칙) 설계서 작성 | G26: 2H | H26: • AI 업무 자동화 교육 경력 3년 이상 • 비개발자 대상 노코드 자동화 교육 경험 • Claude Cowork / Skill 실무 활용 경험 • 관련 분야: AI 리터러시, 업무 프로세스 혁신, DX 컨설팅 등 | I26: [교재] 자체 제작 교재 · 강의별 트렌드 반영 · 자체 제작 및 고도화 [도구] 클로드 Pro 이상, Cowork, Skill, Scheduled Tasks
A27: 훈련목표(목적 등) | B27: 하네스 엔지니어링 프레임워크를 이해하고, Cowork 환경에서 가드레일과 Skill을 설계하여 AI 에이전트를 안전하고 체계적으로 운영할 수 있다. | E27: Module 2. 하네스 구축 실전 — Skill로 AI에게 일하는 법을 가르치다 | F27: ① Skill = 비개발자의 하네스: 반복 작업을 재사용 가능한 규칙으로 저장 - 개발자의 CLAUDE.md가 비개발자에게는 Skill인 이유 - '수동 실행 → 결과 검토 → Skill 저장' 핵심 3단계 흐름 ② 실무 자동화 시나리오 + 가드레일 설계 - 문서 자동화: PDF 추출→엑셀, 영수증→경비 보고서, 회의록→월간 리포트 - 가드레일 실전: '원본 파일 절대 수정 금지', '결과물은 반드시 OO 폴더에' 등 - 피드백 루프: 결과 검토 → 재지시 → Skill 규칙 보완의 개선 사이클 ③ [실습] 실무 업무 1건 Cowork 자동화 + 가드레일 포함 Skill로 저장 | G27: 3H
A28: 훈련대상 | B28: 권장 대상: · Cowork을 써봤지만, AI가 엉뚱한 결과를 낼 때 통제하기 어려웠던 경험이 있는 분 · AI 자동화를 개인뿐 아니라 팀/부서 단위로 확산시키고 싶은 중간 관리자 · 프롬프트만으로 AI를 다루는 한계를 느끼고, 체계적 설계 역량을 키우고 싶은 분 · 비개발자로서 멀티 에이전트 설계자로 성장하고 싶은 분 | E28: Module 3. 기수의 전략 — 스케줄 자동화와 팀 하네스 운영 | F28: ① 스케줄 자동화: Skill로 완전 자동화 - 예약 작업(Scheduled Tasks) 설정: 매일/매주 반복 실행 - 아침 업무 루틴 자동화 시나리오: 이메일 확인→할 일 정리→리포트 생성 - 플러그인 & 커넥터로 하네스 확장: 외부 서비스 연동 맛보기 ② 팀 하네스 운영 전략 - 조직 Skill 라이브러리 구축: 팀원과 Skill 공유, 업무 표준화 - 하네스 고도화 사이클: 사용 → 실패 분석 → 규칙 추가 → 재배포 - 비개발자 기수로의 성장 로드맵: Cowork → Claude Code → 에이전틱 코딩 ③ [실습] Skill + 스케줄 자동화 루틴 완성 및 팀 시연 | G28: 3H
A29: 훈련시간(H) | B29: =VLOOKUP(B26,'2. 신청 훈련과정 정보'!$H$8:$J$1048576,3,0) -> 8
A30: 비대면 실시간 가능 여부 | B30: =VLOOKUP(B26,'2. 신청 훈련과정 정보'!$H$8:$J$1048576,2,0) -> X
A31: 훈련일정 | B31: =VLOOKUP(B26,'2. 신청 훈련과정 정보'!$H$8:$L$1048576,5,0) -> 연중 상시
A32: 과정 소개(요약) 또는 부가 안내 | B32: "AI가 말을 잘 안듣는 다면, 이제는 '설계'할 차례입니다." 프롬프트만으로 AI를 다루면 엉뚱한 파일 삭제, 결과물 불일치 같은 위험이 발생하지만, 하네스를 장착하면 AI가 정해진 범위 내에서 안전하게 일합니다. 본 과정은 Cowork 기반 AI 자동화를 경험한 분들이, 하네스 엔지니어링 프레임워크를 통해 AI를 체계적으로 설계하고 통제하는 역량을 키우는 비개발자 대상 중급 과정입니다.
A35: 연번 | B35: 훈련과정명 | D35: 교과목 | E35: 단원(모듈) | F35: 세부내용 | G35: 편성시간 | H35: 교강사 프로필(요약) | I35: 시설, 장비, 교재
A36: =COUNTIF(INDIRECT("$A$3:A" & ROW()-1), "연번") -> 4 | B36: =VLOOKUP(A36,'2. 신청 훈련과정 정보'!$B$8:$H$1048576,7,0) -> 멀티 에이전트 개발을 위한 하네스 엔지니어링 | D36: 에이전틱 코딩 자동화 실전 | E36: Module 1. 말을 알아야 다룬다 — AI 에이전트와 하네스 엔지니어링 | F36: ① 바이브 코딩 → 에이전틱 코딩: 패러다임 진화 맥락 - 왜 프롬프트만으로는 부족한가: Context Drift와 에이전트 폭주 사례 - 말(AI 모델) / 하네스(환경·제약) / 기수(인간 설계자) 비유 이해 ② 하네스 엔지니어링 3대 핵심 구성 요소 - 가드레일(Guardrail): 입출력 제어와 아키텍처 제약 설계 - 피드백 루프(Feedback Loop): CI/CD, 린터, 구조 테스트 기반 자동 검증 - 컨텍스트 엔지니어링: 에이전트에게 적시에 올바른 정보를 제공하는 설계 ③ [실습] 내 업무 자동화를 위한 하네스 설계 명세서 작성 | G36: 2H | H36: • 소프트웨어 개발/자동화 경력 5년 이상 • AI 에이전트 기반 업무 자동화 프로젝트 수행 경험 • 하네스 엔지니어링 실무 적용 경험 • 관련 분야: 에이전틱 코딩, DevOps, AI 엔지니어링 등 | I36: [교재] 자체 제작 교재 · 강의별 트렌드 반영 · 자체 제작 및 고도화 [도구] 클로드 Pro 이상, Claude code, Skill,
A37: 훈련목표(목적 등) | B37: 하네스 엔지니어링 프레임워크를 기반으로 CLAUDE.md, AGENTS.md, SKILL.md 등 하네스 환경을 구축하고, 멀티 에이전트 오케스트레이션을 설계·실행할 수 있다. | E37: Module 2. 하네스 구축 실전 — 환경 설계와 에이전트 제어 | F37: ① 프로젝트 지시 문서 설계: CLAUDE.md / AGENTS.md 작성 실전 - 프로젝트 구조, 코딩 규칙, 네이밍 컨벤션을 '진실의 원천'으로 문서화 - 에이전트 스킬(SKILL.md) 설계: 반복 작업 절차를 모듈화 ② 가드레일 & 피드백 루프 구축 - 커스텀 린터로 아키텍처 규칙 강제 + 에러 메시지에 수정 지침 주입 - 프롬프트 → 코드 → 실행 → 검증 사이클 실습 ③ [실습] 실무 자동화 1건: 하네스 환경 구축 → 에이전트 실행 → 결과 검증 | G37: 3H
A38: 훈련대상 | B38: 권장 대상: · 클로드 코드 등 AI 코딩 도구를 이미 사용하고 있지만, 체계적 제어 방법론이 필요한 개발자 · AI 에이전트가 코드를 작성할 때 품질 관리와 아키텍처 일관성을 유지하고 싶은 테크 리드 · 멀티 에이전트 기반 개발 파이프라인 구축에 관심 있는 DevOps/AI 엔지니어 · 팀 전체 AI 활용 역량을 상향 평준화하고 싶은 기술 조직 관리자 | E38: Module 3. 기수의 전략 — 멀티 에이전트 오케스트레이션 | F38: ① 멀티 에이전트 하네스 아키텍처 - 역할 분담과 오케스트레이션: 구현·테스트·리뷰 에이전트 분리 - 엔트로피 관리: 코드 부패 방지, 정리 에이전트 설계 ② 조직 차원의 하네스 운영 전략 - 팀 공유 하네스 구축: 표준 설정으로 LLM 활용 역량 상향 평준화 - 에이전트 평가와 지속 개선 사이클: 품질 지표 측정 및 하네스 고도화 ③ [실습] 멀티스텝 하네스 워크플로우 완성 및 팀 시연 | G38: 3H
A39: 훈련시간(H) | B39: =VLOOKUP(B36,'2. 신청 훈련과정 정보'!$H$8:$J$1048576,3,0) -> 8
A40: 비대면 실시간 가능 여부 | B40: =VLOOKUP(B36,'2. 신청 훈련과정 정보'!$H$8:$J$1048576,2,0) -> X
A41: 훈련일정 | B41: =VLOOKUP(B36,'2. 신청 훈련과정 정보'!$H$8:$L$1048576,5,0) -> 연중 상시
A42: 과정 소개(요약) 또는 부가 안내 | B42: "프롬프트만으로는 한계입니다. 진짜 에이전틱 코딩은 하네스에서 시작됩니다." 바이브 코딩은 시작일 뿐, 실무에서는 Context Drift와 에이전트 폭주라는 현실적 문제에 직면합니다. 본 과정은 코딩 경험이 있는 개발자를 대상으로, 하네스 엔지니어링 프레임워크를 활용하여 AI 에이전트를 체계적으로 설계하고 멀티 에이전트 워크플로우까지 구축하는 실전 과정입니다.
A45: 연번 | B45: 훈련과정명 | D45: 교과목 | E45: 단원(모듈) | F45: 세부내용 | G45: 편성시간 | H45: 교강사 프로필(요약) | I45: 시설, 장비, 교재
A46: =COUNTIF(INDIRECT("$A$3:A" & ROW()-1), "연번") -> 5 | B46: =VLOOKUP(A46,'2. 신청 훈련과정 정보'!$B$8:$H$1048576,7,0) -> 상업용 AI콘텐츠 제작 실전 | D46: 상업용 AI 콘텐츠 제작 실전 | E46: Module 1. AI 콘텐츠 컴플라이언스 & 브랜드 프롬프트 설계 | F46: ① AI 컴플라이언스 및 리스크 거버넌스 - AI 저작권, 초상권 등 최신 법규 및 사례 분석 - 기업별 고위험 시나리오 도출 및 대응 가이드 ② 브랜드 가이드 기반 프롬프트 설계 - 브랜드 고유의 페르소나 및 톤앤무드 데이터 학습 - 시스템 프롬프트 설계: 품질 일관성 및 컴플라이언스 체크리스트 반영 | G46: 2H | H46: • 디지털 콘텐츠/크리에이티브 경력 5년 이상 • 생성형 AI 활용 상업 콘텐츠 제작 프로젝트 수행 경험 • 브랜드 캠페인 기획·운영 실무 경험 • 관련 분야: 콘텐츠 프로덕션, 크리에이티브 디렉션, AI 워크플로우 등 | I46: [교재] 자체 제작 교재 · 강의별 트렌드 반영 · 자체 제작 및 고도화 [도구] Nanobanana, Midjourney 등
A47: 훈련목표(목적 등) | B47: AI 저작권·컴플라이언스를 준수하며 브랜드 일관성을 갖춘 상업용 AI 콘텐츠를 기획부터 완성·자산화까지 독립적으로 수행할 수 있다. | E47: Module 2. 프롬프트 매트릭스 기반 시안 생성 및 고도화 | F47: ① 프롬프트 매트릭스 기반 시안 생성 - 변수 조합(구도, 조명, 모델)을 통한 시안 대량 생성 - 브랜드 적합성 검증을 통한 최적 시드(Seed) 선정 ② AI 정밀 보정 및 고도화 - 인페인팅을 통한 디테일(피팅, 신체 등) 교정 - 상업용 색채 및 게시를 위한 업스케일링 | G47: 3H
A48: 훈련대상 | B48: 대상 직무: 사무·경영지원, 기획, 총무, 인사, 마케팅 등 반복 문서 업무가 많은 직무 대상 수준:코딩 경험이 전혀 없는 비개발자 선수 지식: PC 기본 조작 가능, 별도 프로그래밍 지식 불요 권장 대상: · 엑셀 정리, 보고서 작성, 데이터 취합 등 반복 업무에 시간을 많이 쓰는 실무자 · AI 도구를 처음 접하지만 업무 효율화에 관심이 높은 중소기업 임직원 · ChatGPT 등 채팅형 AI는 써봤지만, 파일을 직접 다루는 에이전트형 AI는 처음인 분 | E48: Module 3. 브랜드 패키징 및 기술 자산화 | F48: ① 브랜드 패키징 및 최종 완성 - 정교한 로고/텍스트 삽입 및 브랜드 컬러 매칭 - 매체별(SNS, 커머스 등) 최적화 레이아웃 패키징 ② 기술 자산화 및 아카이빙 - 제작 과정의 기술적 레시피(Seed, 설정값) 기록 - 재사용 가능한 프롬프트 라이브러리 구축 | G48: 3H
A49: 훈련시간(H) | B49: =VLOOKUP(B46,'2. 신청 훈련과정 정보'!$H$8:$J$1048576,3,0) -> 8
A50: 비대면 실시간 가능 여부 | B50: =VLOOKUP(B46,'2. 신청 훈련과정 정보'!$H$8:$J$1048576,2,0) -> X
A51: 훈련일정 | B51: =VLOOKUP(B46,'2. 신청 훈련과정 정보'!$H$8:$L$1048576,5,0) -> 연중 상시
...

Sheet 4. (변경신청 시 작성) 전후대조표
A1: [작성방법(필독!)] (공통) 본 자료는 기승인과정에 대한 변경 신청과정을 대상으로한 추가자료이며, 2번 시트작성과 병행하여 작성/제출하여야 함 1. 연번: 해당 표 내 작성 순서에 따라 기입 2. 과정연번: 승인과정 풀(Pool) 자료 내 기관별 구분 과정연번 기입 / 본 자료 2번 시트에 입력한 해당과정 연번 기입 3. 변경 항목: 과정명 / 과정유형 / 비대면실시간 운영여부 / 교과편성 / 훈련시간 중 해당 항목 기입 (훈련비, 훈련장소 등은 자율 운영 가능하며 훈련인원 제한 없음 -> 변경 신청 대상 항목이 아님)
A4: 연번 | B4: 과정 연번 (승인과정 풀 기준) | C4: 과정 연번 (금회 신청 기준) | D4: 변경 항목 | E4: 종 전 | F4: 변 경 | G4: 비고
A5: 1
A6: 2
A7: 3
A8: 4
A9: 5
A10: 6
A11: 7
A12: 8
A13: 9
A14: 10
